Workbook

Sheet StrapScenario1 Copia
A1: Wash number | B1: ='[1]Final Data (use this)'!C11 | C1: ='[1]Final Data (use this)'!D11 | D1: ='[1]Final Data (use this)'!E3 | E1: ='[1]Final Data (use this)'!F3 | F1: ='[1]Final Data (use this)'!H3 | G1: ='[1]Final Data (use this)'!I3 | H1: ='[1]Final Data (use this)'!J3 | I1: ='[1]Final Data (use this)'!L3 | J1: ='[1]Final Data (use this)'!M3 | K1: ='[1]Final Data (use this)'!O3 | L1: ='[1]Final Data (use this)'!P3 | M1: ='[1]Final Data (use this)'!R3 | N1: ='[1]Final Data (use this)'!S3 | O1: ='[1]Final Data (use this)'!T3 | P1: Ecotoxicity [CTUe/ton resin] | Q1: CAPEX [USD] | R1: OPEX [USD/ton]
A2: Wash 1 | B2: PE | C2: sec-Butyl Acetate | D2: =[2]Process_results_C1_P1!B2+Shredder!$B$2 | F2: =M2 | I2: 1006.01 | J2: 65401.74 | K2: 7403.53 | M2: =[2]Process_results_C1_P1!C2+Shredder!$K$2 | N2: =[2]Process_results_C1_P1!H2+Shredder!$L$2 | O2: =[2]Process_results_C1_P1!I2+Shredder!$M$2 | P2: =[2]Process_results_C1_P1!J2+Shredder!$N$2 | Q2: =[2]Process_results_C1_P1!K2+Shredder!$O$2 | R2: =[2]Process_results_C1_P1!L2+Shredder!$P$2
A3: Wash 1 | B3: PE | C3: Isobutyl Acetate | D3: =[2]Process_results_C1_P1!B3+Shredder!$B$2 | F3: =M3 | I3: 994.95 | J3: 64491.6 | K3: 7463.47 | M3: =[2]Process_results_C1_P1!C3+Shredder!$K$2 | N3: =[2]Process_results_C1_P1!H3+Shredder!$L$2 | O3: =[2]Process_results_C1_P1!I3+Shredder!$M$2 | P3: =[2]Process_results_C1_P1!J3+Shredder!$N$2 | Q3: =[2]Process_results_C1_P1!K3+Shredder!$O$2 | R3: =[2]Process_results_C1_P1!L3+Shredder!$P$2
A4: Wash 1 | B4: PE | C4: Tetrachloroethylene | D4: =[2]Process_results_C1_P1!B4+Shredder!$B$2 | F4: =M4 | I4: 683.96 | J4: 38449.65 | K4: 4419.13 | M4: =[2]Process_results_C1_P1!C4+Shredder!$K$2 | N4: =[2]Process_results_C1_P1!H4+Shredder!$L$2 | O4: =[2]Process_results_C1_P1!I4+Shredder!$M$2 | P4: =[2]Process_results_C1_P1!J4+Shredder!$N$2 | Q4: =[2]Process_results_C1_P1!K4+Shredder!$O$2 | R4: =[2]Process_results_C1_P1!L4+Shredder!$P$2
A5: Wash 1 | B5: PE | C5: o-Chlorotoluene | D5: =[2]Process_results_C1_P1!B5+Shredder!$B$2 | F5: =M5 | I5: 1139.79 | J5: 76633.44 | K5: 6319.81 | M5: =[2]Process_results_C1_P1!C5+Shredder!$K$2 | N5: =[2]Process_results_C1_P1!H5+Shredder!$L$2 | O5: =[2]Process_results_C1_P1!I5+Shredder!$M$2 | P5: =[2]Process_results_C1_P1!J5+Shredder!$N$2 | Q5: =[2]Process_results_C1_P1!K5+Shredder!$O$2 | R5: =[2]Process_results_C1_P1!L5+Shredder!$P$2
A6: Wash 1 | B6: PE | C6: Methylcyclohexane | D6: =[2]Process_results_C1_P1!B6+Shredder!$B$2 | F6: =M6 | I6: 887.08 | J6: 55514.4 | K6: 8129.51 | M6: =[2]Process_results_C1_P1!C6+Shredder!$K$2 | N6: =[2]Process_results_C1_P1!H6+Shredder!$L$2 | O6: =[2]Process_results_C1_P1!I6+Shredder!$M$2 | P6: =[2]Process_results_C1_P1!J6+Shredder!$N$2 | Q6: =[2]Process_results_C1_P1!K6+Shredder!$O$2 | R6: =[2]Process_results_C1_P1!L6+Shredder!$P$2
A7: Wash 1 | B7: PE | C7: Dodecanol | D7: =[2]Process_results_C1_P1!B7+Shredder!$B$2 | F7: =M7 | I7: 2487.39 | J7: 187927.49 | K7: 8514.94 | M7: =[2]Process_results_C1_P1!C7+Shredder!$K$2 | N7: =[2]Process_results_C1_P1!H7+Shredder!$L$2 | O7: =[2]Process_results_C1_P1!I7+Shredder!$M$2 | P7: =[2]Process_results_C1_P1!J7+Shredder!$N$2 | Q7: =[2]Process_results_C1_P1!K7+Shredder!$O$2 | R7: =[2]Process_results_C1_P1!L7+Shredder!$P$2
A8: Wash 1 | B8: PE | C8: Heptane | D8: =[2]Process_results_C1_P1!B8+Shredder!$B$2 | F8: =M8 | I8: 920.27 | J8: 58179.21 | K8: 9006.42 | M8: =[2]Process_results_C1_P1!C8+Shredder!$K$2 | N8: =[2]Process_results_C1_P1!H8+Shredder!$L$2 | O8: =[2]Process_results_C1_P1!I8+Shredder!$M$2 | P8: =[2]Process_results_C1_P1!J8+Shredder!$N$2 | Q8: =[2]Process_results_C1_P1!K8+Shredder!$O$2 | R8: =[2]Process_results_C1_P1!L8+Shredder!$P$2
A9: Wash 1 | B9: PE | C9: Toluene | D9: =[2]Process_results_C1_P1!B9+Shredder!$B$2 | F9: =M9 | I9: 1040.73 | J9: 67836.93 | K9: 11871.24 | M9: =[2]Process_results_C1_P1!C9+Shredder!$K$2 | N9: =[2]Process_results_C1_P1!H9+Shredder!$L$2 | O9: =[2]Process_results_C1_P1!I9+Shredder!$M$2 | P9: =[2]Process_results_C1_P1!J9+Shredder!$N$2 | Q9: =[2]Process_results_C1_P1!K9+Shredder!$O$2 | R9: =[2]Process_results_C1_P1!L9+Shredder!$P$2
A10: Wash 1 | B10: PE | C10: Xylene | D10: =[2]Process_results_C1_P1!B10+Shredder!$B$2 | F10: =M10 | I10: 1159.2 | J10: 78331.71 | K10: 7294.56 | M10: =[2]Process_results_C1_P1!C10+Shredder!$K$2 | N10: =[2]Process_results_C1_P1!H10+Shredder!$L$2 | O10: =[2]Process_results_C1_P1!I10+Shredder!$M$2 | P10: =[2]Process_results_C1_P1!J10+Shredder!$N$2 | Q10: =[2]Process_results_C1_P1!K10+Shredder!$O$2 | R10: =[2]Process_results_C1_P1!L10+Shredder!$P$2
A11: Wash 1 | B11: EVOH | C11: =[3]Process_results_C1_E1!$A$2 | D11: =[3]Process_results_C1_E1!B2+Shredder!$B$2 | F11: =M11 | I11: 1512.92 | J11: 125060.56 | K11: 2426.35 | M11: =[3]Process_results_C1_E1!C2+Shredder!$K$2 | N11: =[3]Process_results_C1_E1!H2+Shredder!$L$2 | O11: =[3]Process_results_C1_E1!I2+Shredder!$M$2 | P11: =[3]Process_results_C1_E1!J2+Shredder!$N$2 | Q11: =[3]Process_results_C1_E1!K2+Shredder!$O$2 | R11: =[3]Process_results_C1_E1!L2+Shredder!$P$2
A12: Wash 1 | B12: EVOH | C12: =[3]Process_results_C1_E1!$A$3 | D12: =[3]Process_results_C1_E1!B3+Shredder!$B$2 | F12: =M12 | I12: 964.84 | J12: 76612.87 | K12: 2837.85 | M12: =[3]Process_results_C1_E1!C3+Shredder!$K$2 | N12: =[3]Process_results_C1_E1!H3+Shredder!$L$2 | O12: =[3]Process_results_C1_E1!I3+Shredder!$M$2 | P12: =[3]Process_results_C1_E1!J3+Shredder!$N$2 | Q12: =[3]Process_results_C1_E1!K3+Shredder!$O$2 | R12: =[3]Process_results_C1_E1!L3+Shredder!$P$2
A13: Wash 2 | B13: PE | C13: sec-Butyl Acetate | D13: 5.02 | F13: =M13 | I13: 966.49 | J13: 62262.96 | K13: 7303.6 | M13: 1.2005329 | N13: 4.5338019e-08 | O13: 2.5078508e-08 | P13: 1.2777775 | Q13: 40931215 | R13: 1047740.1
A14: Wash 2 | B14: PE | C14: Isobutyl Acetate | D14: 5.02 | F14: =M14 | I14: 958.02 | J14: 61569.48 | K14: 7363.19 | M14: 1.196813 | N14: 4.5246416e-08 | O14: 2.5090223e-08 | P14: 1.2774454 | Q14: 41185362 | R14: 1052268.2
A15: Wash 2 | B15: PE | C15: Tetrachloroethylene | D15: 4.8 | F15: =M15 | I15: 656.12 | J15: 36362.45 | K15: 4341.89 | M15: 1.0965103 | N15: 3.9866638e-08 | O15: 2.1764279e-08 | P15: 1.0740143 | Q15: 35754823 | R15: 938269.24
A16: Wash 2 | B16: PE | C16: o-Chlorotoluene | D16: 5.01 | F16: =M16 | I16: 1098.51 | J16: 73352.38 | K16: 6226.9 | M16: 1.2365479 | N16: 4.6334882e-08 | O16: 2.5177552e-08 | P16: 1.2972699 | Q16: 39697204 | R16: 1028423.1
A17: Wash 2 | B17: PE | C17: Methylcyclohexane | D17: 5.01 | F17: =M17 | I17: 846.45 | J17: 52253.34 | K17: 8025.78 | M17: 1.1562855 | N17: 4.2921731e-08 | O17: 2.2988628e-08 | P17: 1.1816403 | Q17: 41755740 | R17: 1059416.7
A18: Wash 2 | B18: PE | C18: Dodecanol | D18: 5.48 | F18: =M18 | I18: 2419.67 | J18: 182520.62 | K18: 8405.55 | M18: 1.7207436 | N18: 6.5314505e-08 | O18: 3.977586e-08 | P18: 1.9967304 | Q18: 45094364 | R18: 1186252
A19: Wash 2 | B19: PE | C19: Heptane | D19: 5.06 | F19: =M19 | I19: 880.03 | J19: 54950.96 | K19: 8897.14 | M19: 1.1688554 | N19: 4.3001802e-08 | O19: 2.2719875e-08 | P19: 1.1656356 | Q19: 43208033 | R19: 1088889.2
A20: Wash 2 | B20: PE | C20: Toluene | D20: 5.18 | F20: =M20 | I20: 993.67 | J20: 64056.57 | K20: 11716.23 | M20: 1.2141233 | N20: 4.5108743e-08 | O20: 2.3876385e-08 | P20: 1.2302914 | Q20: 46986127 | R20: 1179441.8
A21: Wash 2 | B21: PE | C21: Xylene | D21: 5.06 | F21: =M21 | I21: 1117.99 | J21: 75028.67 | K21: 7194.85 | M21: 1.2384899 | N21: 4.5663809e-08 | O21: 2.4004406e-08 | P21: 1.235194 | Q21: 41234664 | R21: 1058246.1
A22: Wash 2 | B22: EVOH | C22: butane-1,4-diol | D22: =[4]Process_results_C1_E2!B2*Shredder!$B$2 | F22: =M22 | I22: =[4]Process_results_C1_E2!F2 | J22: =[4]Process_results_C1_E2!G2 | K22: =[4]Process_results_C1_E2!D2 | M22: =[4]Process_results_C1_E2!C2+Shredder!$K$2 | N22: =[4]Process_results_C1_E2!H2+Shredder!$L$2 | O22: =[4]Process_results_C1_E2!I2+Shredder!$M$2 | P22: =[4]Process_results_C1_E2!J2+Shredder!$N$2 | Q22: =[4]Process_results_C1_E2!K2+Shredder!$O$2 | R22: =[4]Process_results_C1_E2!L2+Shredder!$P$2
A23: Wash 2 | B23: EVOH | C23: Diethanolamine | D23: =[4]Process_results_C1_E2!B3*Shredder!$B$2 | F23: =M23 | I23: =[4]Process_results_C1_E2!F3 | J23: =[4]Process_results_C1_E2!G3 | K23: =[4]Process_results_C1_E2!D3 | M23: =[4]Process_results_C1_E2!C3+Shredder!$K$2 | N23: =[4]Process_results_C1_E2!H3+Shredder!$L$2 | O23: =[4]Process_results_C1_E2!I3+Shredder!$M$2 | P23: =[4]Process_results_C1_E2!J3+Shredder!$N$2 | Q23: =[4]Process_results_C1_E2!K3+Shredder!$O$2 | R23: =[4]Process_results_C1_E2!L3+Shredder!$P$2
A24: Wash 2 | B24: EVOH | C24: Diethylene glycol | D24: =[4]Process_results_C1_E2!B4*Shredder!$B$2 | F24: =M24 | I24: =[4]Process_results_C1_E2!F4 | J24: =[4]Process_results_C1_E2!G4 | K24: =[4]Process_results_C1_E2!D4 | M24: =[4]Process_results_C1_E2!C4+Shredder!$K$2 | N24: =[4]Process_results_C1_E2!H4+Shredder!$L$2 | O24: =[4]Process_results_C1_E2!I4+Shredder!$M$2 | P24: =[4]Process_results_C1_E2!J4+Shredder!$N$2 | Q24: =[4]Process_results_C1_E2!K4+Shredder!$O$2 | R24: =[4]Process_results_C1_E2!L4+Shredder!$P$2
A25: Wash 2 | B25: EVOH | C25: Ethylene Glycol | D25: =[4]Process_results_C1_E2!B5*Shredder!$B$2 | F25: =M25 | I25: =[4]Process_results_C1_E2!F5 | J25: =[4]Process_results_C1_E2!G5 | K25: =[4]Process_results_C1_E2!D5 | M25: =[4]Process_results_C1_E2!C5+Shredder!$K$2 | N25: =[4]Process_results_C1_E2!H5+Shredder!$L$2 | O25: =[4]Process_results_C1_E2!I5+Shredder!$M$2 | P25: =[4]Process_results_C1_E2!J5+Shredder!$N$2 | Q25: =[4]Process_results_C1_E2!K5+Shredder!$O$2 | R25: =[4]Process_results_C1_E2!L5+Shredder!$P$2
A26: Wash 2 | B26: EVOH | C26: Propylene Glycol | D26: =[4]Process_results_C1_E2!B6*Shredder!$B$2 | F26: =M26 | I26: =[4]Process_results_C1_E2!F6 | J26: =[4]Process_results_C1_E2!G6 | K26: =[4]Process_results_C1_E2!D6 | M26: =[4]Process_results_C1_E2!C6+Shredder!$K$2 | N26: =[4]Process_results_C1_E2!H6+Shredder!$L$2 | O26: =[4]Process_results_C1_E2!I6+Shredder!$M$2 | P26: =[4]Process_results_C1_E2!J6+Shredder!$N$2 | Q26: =[4]Process_results_C1_E2!K6+Shredder!$O$2 | R26: =[4]Process_results_C1_E2!L6+Shredder!$P$2
A27: Wash 2 | B27: EVOH | C27: Pyridazine | D27: =[4]Process_results_C1_E2!B7*Shredder!$B$2 | F27: =M27 | I27: =[4]Process_results_C1_E2!F7 | J27: =[4]Process_results_C1_E2!G7 | K27: =[4]Process_results_C1_E2!D7 | M27: =[4]Process_results_C1_E2!C7+Shredder!$K$2 | N27: =[4]Process_results_C1_E2!H7+Shredder!$L$2 | O27: =[4]Process_results_C1_E2!I7+Shredder!$M$2 | P27: =[4]Process_results_C1_E2!J7+Shredder!$N$2 | Q27: =[4]Process_results_C1_E2!K7+Shredder!$O$2 | R27: =[4]Process_results_C1_E2!L7+Shredder!$P$2
A28: Wash 2 | B28: EVOH | C28: gamma-butyrolactone | D28: =[4]Process_results_C1_E2!B8*Shredder!$B$2 | F28: =M28 | I28: =[4]Process_results_C1_E2!F8 | J28: =[4]Process_results_C1_E2!G8 | K28: =[4]Process_results_C1_E2!D8 | M28: =[4]Process_results_C1_E2!C8+Shredder!$K$2 | N28: =[4]Process_results_C1_E2!H8+Shredder!$L$2 | O28: =[4]Process_results_C1_E2!I8+Shredder!$M$2 | P28: =[4]Process_results_C1_E2!J8+Shredder!$N$2 | Q28: =[4]Process_results_C1_E2!K8+Shredder!$O$2 | R28: =[4]Process_results_C1_E2!L8+Shredder!$P$2

Sheet StrapScenario1 Units
A1: Wash number | B1: Polymer | C1: Solvents | D1: Total Energy Consumed [MJ/yr] | E1: Total Renewable Energy Consumed [MJ/yr] | F1: Total Direct GHG emissions [Scope 1] [metric tons CO2 equivalent [tCO2e/yr]] | G1: Total Energy indirect GHG emissions (Scope 2) [metric tons CO2 equivalent (t CO2e/yr)] | H1: Water consumed/discarded [m3/yr] | I1: Water Recycled or Reused [m3/yr] | J1: Waste generated - Non Hazardous [kg/yr] | K1: Waste to Disposal[ton/yr] | L1: GWP [tonCO2e/yr] | M1: Human toxicity cancer [CTUh/yr] | N1: Human toxicity non-cancer [CTUh/yr] | O1: Ecotoxicity [CTUe/yr] | P1: CAPEX [USD/yr] | Q1: OPEX [USD/yr]
A2: =StrapScenario1!A2 | B2: =StrapScenario1!B2 | C2: =StrapScenario1!C2 | D2: =StrapScenario1!D2*'[1]New UBs'!$E$50 | E2: =StrapScenario1!E2 | F2: =L2 | G2: =StrapScenario1!G2 | H2: =StrapScenario1!H2 | I2: =StrapScenario1!I2 | J2: =StrapScenario1!J2 | K2: =StrapScenario1!K2 | L2: =StrapScenario1!L2*'[1]New UBs'!$E$50/1000 | M2: =StrapScenario1!M2*'[1]New UBs'!$E$50 | N2: =StrapScenario1!N2*'[1]New UBs'!$E$50 | O2: =StrapScenario1!O2*'[1]New UBs'!$E$50 | P2: =StrapScenario1!P2/20 | Q2: =StrapScenario1!Q2
A3: =StrapScenario1!A3 | B3: =StrapScenario1!B3 | C3: =StrapScenario1!C3 | D3: =StrapScenario1!D3*'[1]New UBs'!$E$50 | E3: =StrapScenario1!E3 | F3: =L3 | G3: =StrapScenario1!G3 | H3: =StrapScenario1!H3 | I3: =StrapScenario1!I3 | J3: =StrapScenario1!J3 | K3: =StrapScenario1!K3 | L3: =StrapScenario1!L3*'[1]New UBs'!$E$50/1000 | M3: =StrapScenario1!M3*'[1]New UBs'!$E$50 | N3: =StrapScenario1!N3*'[1]New UBs'!$E$50 | O3: =StrapScenario1!O3*'[1]New UBs'!$E$50 | P3: =StrapScenario1!P3/20 | Q3: =StrapScenario1!Q3
A4: =StrapScenario1!A4 | B4: =StrapScenario1!B4 | C4: =StrapScenario1!C4 | D4: =StrapScenario1!D4*'[1]New UBs'!$E$50 | E4: =StrapScenario1!E4 | F4: =L4 | G4: =StrapScenario1!G4 | H4: =StrapScenario1!H4 | I4: =StrapScenario1!I4 | J4: =StrapScenario1!J4 | K4: =StrapScenario1!K4 | L4: =StrapScenario1!L4*'[1]New UBs'!$E$50/1000 | M4: =StrapScenario1!M4*'[1]New UBs'!$E$50 | N4: =StrapScenario1!N4*'[1]New UBs'!$E$50 | O4: =StrapScenario1!O4*'[1]New UBs'!$E$50 | P4: =StrapScenario1!P4/20 | Q4: =StrapScenario1!Q4
A5: =StrapScenario1!A5 | B5: =StrapScenario1!B5 | C5: =StrapScenario1!C5 | D5: =StrapScenario1!D5*'[1]New UBs'!$E$50 | E5: =StrapScenario1!E5 | F5: =L5 | G5: =StrapScenario1!G5 | H5: =StrapScenario1!H5 | I5: =StrapScenario1!I5 | J5: =StrapScenario1!J5 | K5: =StrapScenario1!K5 | L5: =StrapScenario1!L5*'[1]New UBs'!$E$50/1000 | M5: =StrapScenario1!M5*'[1]New UBs'!$E$50 | N5: =StrapScenario1!N5*'[1]New UBs'!$E$50 | O5: =StrapScenario1!O5*'[1]New UBs'!$E$50 | P5: =StrapScenario1!P5/20 | Q5: =StrapScenario1!Q5
A6: =StrapScenario1!A6 | B6: =StrapScenario1!B6 | C6: =StrapScenario1!C6 | D6: =StrapScenario1!D6*'[1]New UBs'!$E$50 | E6: =StrapScenario1!E6 | F6: =L6 | G6: =StrapScenario1!G6 | H6: =StrapScenario1!H6 | I6: =StrapScenario1!I6 | J6: =StrapScenario1!J6 | K6: =StrapScenario1!K6 | L6: =StrapScenario1!L6*'[1]New UBs'!$E$50/1000 | M6: =StrapScenario1!M6*'[1]New UBs'!$E$50 | N6: =StrapScenario1!N6*'[1]New UBs'!$E$50 | O6: =StrapScenario1!O6*'[1]New UBs'!$E$50 | P6: =StrapScenario1!P6/20 | Q6: =StrapScenario1!Q6
A7: =StrapScenario1!A7 | B7: =StrapScenario1!B7 | C7: =StrapScenario1!C7 | D7: =StrapScenario1!D7*'[1]New UBs'!$E$50 | E7: =StrapScenario1!E7 | F7: =L7 | G7: =StrapScenario1!G7 | H7: =StrapScenario1!H7 | I7: =StrapScenario1!I7 | J7: =StrapScenario1!J7 | K7: =StrapScenario1!K7 | L7: =StrapScenario1!L7*'[1]New UBs'!$E$50/1000 | M7: =StrapScenario1!M7*'[1]New UBs'!$E$50 | N7: =StrapScenario1!N7*'[1]New UBs'!$E$50 | O7: =StrapScenario1!O7*'[1]New UBs'!$E$50 | P7: =StrapScenario1!P7/20 | Q7: =StrapScenario1!Q7
A8: =StrapScenario1!A8 | B8: =StrapScenario1!B8 | C8: =StrapScenario1!C8 | D8: =StrapScenario1!D8*'[1]New UBs'!$E$50 | E8: =StrapScenario1!E8 | F8: =L8 | G8: =StrapScenario1!G8 | H8: =StrapScenario1!H8 | I8: =StrapScenario1!I8 | J8: =StrapScenario1!J8 | K8: =StrapScenario1!K8 | L8: =StrapScenario1!L8*'[1]New UBs'!$E$50/1000 | M8: =StrapScenario1!M8*'[1]New UBs'!$E$50 | N8: =StrapScenario1!N8*'[1]New UBs'!$E$50 | O8: =StrapScenario1!O8*'[1]New UBs'!$E$50 | P8: =StrapScenario1!P8/20 | Q8: =StrapScenario1!Q8
A9: =StrapScenario1!A9 | B9: =StrapScenario1!B9 | C9: =StrapScenario1!C9 | D9: =StrapScenario1!D9*'[1]New UBs'!$E$50 | E9: =StrapScenario1!E9 | F9: =L9 | G9: =StrapScenario1!G9 | H9: =StrapScenario1!H9 | I9: =StrapScenario1!I9 | J9: =StrapScenario1!J9 | K9: =StrapScenario1!K9 | L9: =StrapScenario1!L9*'[1]New UBs'!$E$50/1000 | M9: =StrapScenario1!M9*'[1]New UBs'!$E$50 | N9: =StrapScenario1!N9*'[1]New UBs'!$E$50 | O9: =StrapScenario1!O9*'[1]New UBs'!$E$50 | P9: =StrapScenario1!P9/20 | Q9: =StrapScenario1!Q9
A10: =StrapScenario1!A10 | B10: =StrapScenario1!B10 | C10: =StrapScenario1!C10 | D10: =StrapScenario1!D10*'[1]New UBs'!$E$50 | E10: =StrapScenario1!E10 | F10: =L10 | G10: =StrapScenario1!G10 | H10: =StrapScenario1!H10 | I10: =StrapScenario1!I10 | J10: =StrapScenario1!J10 | K10: =StrapScenario1!K10 | L10: =StrapScenario1!L10*'[1]New UBs'!$E$50/1000 | M10: =StrapScenario1!M10*'[1]New UBs'!$E$50 | N10: =StrapScenario1!N10*'[1]New UBs'!$E$50 | O10: =StrapScenario1!O10*'[1]New UBs'!$E$50 | P10: =StrapScenario1!P10/20 | Q10: =StrapScenario1!Q10
A11: =StrapScenario1!A11 | B11: =StrapScenario1!B11 | C11: =StrapScenario1!C11 | D11: =StrapScenario1!D11*'[1]New UBs'!$E$51 | E11: =StrapScenario1!E11 | F11: =L11 | G11: =StrapScenario1!G11 | H11: =StrapScenario1!H11 | I11: =StrapScenario1!I11 | J11: =StrapScenario1!J11 | K11: =StrapScenario1!K11 | L11: =StrapScenario1!L11*'[1]New UBs'!$E$51/1000 | M11: =StrapScenario1!M11*'[1]New UBs'!$E$51 | N11: =StrapScenario1!N11*'[1]New UBs'!$E$51 | O11: =StrapScenario1!O11*'[1]New UBs'!$E$51 | P11: =StrapScenario1!P11/20 | Q11: =StrapScenario1!Q11
A12: =StrapScenario1!A12 | B12: =StrapScenario1!B12 | C12: =StrapScenario1!C12 | D12: =StrapScenario1!D12*'[1]New UBs'!$E$51 | E12: =StrapScenario1!E12 | F12: =L12 | G12: =StrapScenario1!G12 | H12: =StrapScenario1!H12 | I12: =StrapScenario1!I12 | J12: =StrapScenario1!J12 | K12: =StrapScenario1!K12 | L12: =StrapScenario1!L12*'[1]New UBs'!$E$51/1000 | M12: =StrapScenario1!M12*'[1]New UBs'!$E$51 | N12: =StrapScenario1!N12*'[1]New UBs'!$E$51 | O12: =StrapScenario1!O12*'[1]New UBs'!$E$51 | P12: =StrapScenario1!P12/20 | Q12: =StrapScenario1!Q12
A13: =StrapScenario1!A13 | B13: =StrapScenario1!B13 | C13: =StrapScenario1!C13 | D13: =StrapScenario1!D13*'[1]New UBs'!$J$51 | E13: =StrapScenario1!E13 | F13: =L13 | G13: =StrapScenario1!G13 | H13: =StrapScenario1!H13 | I13: =StrapScenario1!I13 | J13: =StrapScenario1!J13 | K13: =StrapScenario1!K13 | L13: =StrapScenario1!L13*'[1]New UBs'!$J$51/1000 | M13: =StrapScenario1!M13*'[1]New UBs'!$J$50 | N13: =StrapScenario1!N13*'[1]New UBs'!$J$51 | O13: =StrapScenario1!O13*'[1]New UBs'!$J$51 | P13: =StrapScenario1!P13/20 | Q13: =StrapScenario1!Q13
A14: =StrapScenario1!A14 | B14: =StrapScenario1!B14 | C14: =StrapScenario1!C14 | D14: =StrapScenario1!D14*'[1]New UBs'!$J$51 | E14: =StrapScenario1!E14 | F14: =L14 | G14: =StrapScenario1!G14 | H14: =StrapScenario1!H14 | I14: =StrapScenario1!I14 | J14: =StrapScenario1!J14 | K14: =StrapScenario1!K14 | L14: =StrapScenario1!L14*'[1]New UBs'!$J$51/1000 | M14: =StrapScenario1!M14*'[1]New UBs'!$J$50 | N14: =StrapScenario1!N14*'[1]New UBs'!$J$51 | O14: =StrapScenario1!O14*'[1]New UBs'!$J$51 | P14: =StrapScenario1!P14/20 | Q14: =StrapScenario1!Q14
A15: =StrapScenario1!A15 | B15: =StrapScenario1!B15 | C15: =StrapScenario1!C15 | D15: =StrapScenario1!D15*'[1]New UBs'!$J$51 | E15: =StrapScenario1!E15 | F15: =L15 | G15: =StrapScenario1!G15 | H15: =StrapScenario1!H15 | I15: =StrapScenario1!I15 | J15: =StrapScenario1!J15 | K15: =StrapScenario1!K15 | L15: =StrapScenario1!L15*'[1]New UBs'!$J$51/1000 | M15: =StrapScenario1!M15*'[1]New UBs'!$J$50 | N15: =StrapScenario1!N15*'[1]New UBs'!$J$51 | O15: =StrapScenario1!O15*'[1]New UBs'!$J$51 | P15: =StrapScenario1!P15/20 | Q15: =StrapScenario1!Q15
A16: =StrapScenario1!A16 | B16: =StrapScenario1!B16 | C16: =StrapScenario1!C16 | D16: =StrapScenario1!D16*'[1]New UBs'!$J$51 | E16: =StrapScenario1!E16 | F16: =L16 | G16: =StrapScenario1!G16 | H16: =StrapScenario1!H16 | I16: =StrapScenario1!I16 | J16: =StrapScenario1!J16 | K16: =StrapScenario1!K16 | L16: =StrapScenario1!L16*'[1]New UBs'!$J$51/1000 | M16: =StrapScenario1!M16*'[1]New UBs'!$J$50 | N16: =StrapScenario1!N16*'[1]New UBs'!$J$51 | O16: =StrapScenario1!O16*'[1]New UBs'!$J$51 | P16: =StrapScenario1!P16/20 | Q16: =StrapScenario1!Q16
A17: =StrapScenario1!A17 | B17: =StrapScenario1!B17 | C17: =StrapScenario1!C17 | D17: =StrapScenario1!D17*'[1]New UBs'!$J$51 | E17: =StrapScenario1!E17 | F17: =L17 | G17: =StrapScenario1!G17 | H17: =StrapScenario1!H17 | I17: =StrapScenario1!I17 | J17: =StrapScenario1!J17 | K17: =StrapScenario1!K17 | L17: =StrapScenario1!L17*'[1]New UBs'!$J$51/1000 | M17: =StrapScenario1!M17*'[1]New UBs'!$J$50 | N17: =StrapScenario1!N17*'[1]New UBs'!$J$51 | O17: =StrapScenario1!O17*'[1]New UBs'!$J$51 | P17: =StrapScenario1!P17/20 | Q17: =StrapScenario1!Q17
A18: =StrapScenario1!A18 | B18: =StrapScenario1!B18 | C18: =StrapScenario1!C18 | D18: =StrapScenario1!D18*'[1]New UBs'!$J$51 | E18: =StrapScenario1!E18 | F18: =L18 | G18: =StrapScenario1!G18 | H18: =StrapScenario1!H18 | I18: =StrapScenario1!I18 | J18: =StrapScenario1!J18 | K18: =StrapScenario1!K18 | L18: =StrapScenario1!L18*'[1]New UBs'!$J$51/1000 | M18: =StrapScenario1!M18*'[1]New UBs'!$J$50 | N18: =StrapScenario1!N18*'[1]New UBs'!$J$51 | O18: =StrapScenario1!O18*'[1]New UBs'!$J$51 | P18: =StrapScenario1!P18/20 | Q18: =StrapScenario1!Q18
A19: =StrapScenario1!A19 | B19: =StrapScenario1!B19 | C19: =StrapScenario1!C19 | D19: =StrapScenario1!D19*'[1]New UBs'!$J$51 | E19: =StrapScenario1!E19 | F19: =L19 | G19: =StrapScenario1!G19 | H19: =StrapScenario1!H19 | I19: =StrapScenario1!I19 | J19: =StrapScenario1!J19 | K19: =StrapScenario1!K19 | L19: =StrapScenario1!L19*'[1]New UBs'!$J$51/1000 | M19: =StrapScenario1!M19*'[1]New UBs'!$J$50 | N19: =StrapScenario1!N19*'[1]New UBs'!$J$51 | O19: =StrapScenario1!O19*'[1]New UBs'!$J$51 | P19: =StrapScenario1!P19/20 | Q19: =StrapScenario1!Q19
A20: =StrapScenario1!A20 | B20: =StrapScenario1!B20 | C20: =StrapScenario1!C20 | D20: =StrapScenario1!D20*'[1]New UBs'!$J$51 | E20: =StrapScenario1!E20 | F20: =L20 | G20: =StrapScenario1!G20 | H20: =StrapScenario1!H20 | I20: =StrapScenario1!I20 | J20: =StrapScenario1!J20 | K20: =StrapScenario1!K20 | L20: =StrapScenario1!L20*'[1]New UBs'!$J$51/1000 | M20: =StrapScenario1!M20*'[1]New UBs'!$J$50 | N20: =StrapScenario1!N20*'[1]New UBs'!$J$51 | O20: =StrapScenario1!O20*'[1]New UBs'!$J$51 | P20: =StrapScenario1!P20/20 | Q20: =StrapScenario1!Q20
A21: =StrapScenario1!A21 | B21: =StrapScenario1!B21 | C21: =StrapScenario1!C21 | D21: =StrapScenario1!D21*'[1]New UBs'!$J$51 | E21: =StrapScenario1!E21 | F21: =L21 | G21: =StrapScenario1!G21 | H21: =StrapScenario1!H21 | I21: =StrapScenario1!I21 | J21: =StrapScenario1!J21 | K21: =StrapScenario1!K21 | L21: =StrapScenario1!L21*'[1]New UBs'!$J$51/1000 | M21: =StrapScenario1!M21*'[1]New UBs'!$J$50 | N21: =StrapScenario1!N21*'[1]New UBs'!$J$51 | O21: =StrapScenario1!O21*'[1]New UBs'!$J$51 | P21: =StrapScenario1!P21/20 | Q21: =StrapScenario1!Q21
A22: =StrapScenario1!A22 | B22: =StrapScenario1!B22 | C22: =StrapScenario1!C22 | D22: =StrapScenario1!D22*'[1]New UBs'!$J$50 | E22: =StrapScenario1!E22 | F22: =L22 | G22: =StrapScenario1!G22 | H22: =StrapScenario1!H22 | I22: =StrapScenario1!I22 | J22: =StrapScenario1!J22 | K22: =StrapScenario1!K22 | L22: =StrapScenario1!L22*'[1]New UBs'!$J$50/1000 | M22: =StrapScenario1!M22*'[1]New UBs'!$J$51 | N22: =StrapScenario1!N22*'[1]New UBs'!$J$50 | O22: =StrapScenario1!O22*'[1]New UBs'!$J$50 | P22: =StrapScenario1!P22/20 | Q22: =StrapScenario1!Q22
A23: =StrapScenario1!A23 | B23: =StrapScenario1!B23 | C23: =StrapScenario1!C23 | D23: =StrapScenario1!D23*'[1]New UBs'!$J$50 | E23: =StrapScenario1!E23 | F23: =L23 | G23: =StrapScenario1!G23 | H23: =StrapScenario1!H23 | I23: =StrapScenario1!I23 | J23: =StrapScenario1!J23 | K23: =StrapScenario1!K23 | L23: =StrapScenario1!L23*'[1]New UBs'!$J$50/1000 | M23: =StrapScenario1!M23*'[1]New UBs'!$J$51 | N23: =StrapScenario1!N23*'[1]New UBs'!$J$50 | O23: =StrapScenario1!O23*'[1]New UBs'!$J$50 | P23: =StrapScenario1!P23/20 | Q23: =StrapScenario1!Q23
A24: =StrapScenario1!A24 | B24: =StrapScenario1!B24 | C24: =StrapScenario1!C24 | D24: =StrapScenario1!D24*'[1]New UBs'!$J$50 | E24: =StrapScenario1!E24 | F24: =L24 | G24: =StrapScenario1!G24 | H24: =StrapScenario1!H24 | I24: =StrapScenario1!I24 | J24: =StrapScenario1!J24 | K24: =StrapScenario1!K24 | L24: =StrapScenario1!L24*'[1]New UBs'!$J$50/1000 | M24: =StrapScenario1!M24*'[1]New UBs'!$J$51 | N24: =StrapScenario1!N24*'[1]New UBs'!$J$50 | O24: =StrapScenario1!O24*'[1]New UBs'!$J$50 | P24: =StrapScenario1!P24/20 | Q24: =StrapScenario1!Q24
A25: =StrapScenario1!A25 | B25: =StrapScenario1!B25 | C25: =StrapScenario1!C25 | D25: =StrapScenario1!D25*'[1]New UBs'!$J$50 | E25: =StrapScenario1!E25 | F25: =L25 | G25: =StrapScenario1!G25 | H25: =StrapScenario1!H25 | I25: =StrapScenario1!I25 | J25: =StrapScenario1!J25 | K25: =StrapScenario1!K25 | L25: =StrapScenario1!L25*'[1]New UBs'!$J$50/1000 | M25: =StrapScenario1!M25*'[1]New UBs'!$J$51 | N25: =StrapScenario1!N25*'[1]New UBs'!$J$50 | O25: =StrapScenario1!O25*'[1]New UBs'!$J$50 | P25: =StrapScenario1!P25/20 | Q25: =StrapScenario1!Q25
A26: =StrapScenario1!A26 | B26: =StrapScenario1!B26 | C26: =StrapScenario1!C26 | D26: =StrapScenario1!D26*'[1]New UBs'!$J$50 | E26: =StrapScenario1!E26 | F26: =L26 | G26: =StrapScenario1!G26 | H26: =StrapScenario1!H26 | I26: =StrapScenario1!I26 | J26: =StrapScenario1!J26 | K26: =StrapScenario1!K26 | L26: =StrapScenario1!L26*'[1]New UBs'!$J$50/1000 | M26: =StrapScenario1!M26*'[1]New UBs'!$J$51 | N26: =StrapScenario1!N26*'[1]New UBs'!$J$50 | O26: =StrapScenario1!O26*'[1]New UBs'!$J$50 | P26: =StrapScenario1!P26/20 | Q26: =StrapScenario1!Q26
A27: =StrapScenario1!A27 | B27: =StrapScenario1!B27 | C27: =StrapScenario1!C27 | D27: =StrapScenario1!D27*'[1]New UBs'!$J$50 | E27: =StrapScenario1!E27 | F27: =L27 | G27: =StrapScenario1!G27 | H27: =StrapScenario1!H27 | I27: =StrapScenario1!I27 | J27: =StrapScenario1!J27 | K27: =StrapScenario1!K27 | L27: =StrapScenario1!L27*'[1]New UBs'!$J$50/1000 | M27: =StrapScenario1!M27*'[1]New UBs'!$J$51 | N27: =StrapScenario1!N27*'[1]New UBs'!$J$50 | O27: =StrapScenario1!O27*'[1]New UBs'!$J$50 | P27: =StrapScenario1!P27/20 | Q27: =StrapScenario1!Q27
A28: =StrapScenario1!A28 | B28: =StrapScenario1!B28 | C28: =StrapScenario1!C28 | D28: =StrapScenario1!D28*'[1]New UBs'!$J$50 | E28: =StrapScenario1!E28 | F28: =L28 | G28: =StrapScenario1!G28 | H28: =StrapScenario1!H28 | I28: =StrapScenario1!I28 | J28: =StrapScenario1!J28 | K28: =StrapScenario1!K28 | L28: =StrapScenario1!L28*'[1]New UBs'!$J$50/1000 | M28: =StrapScenario1!M28*'[1]New UBs'!$J$51 | N28: =StrapScenario1!N28*'[1]New UBs'!$J$50 | O28: =StrapScenario1!O28*'[1]New UBs'!$J$50 | P28: =StrapScenario1!P28/20 | Q28: =StrapScenario1!Q28

Sheet Sheet3
B3: profit | C3: ce
B6: 4476300.1 | C6: 0.7236345
B7: 7876773.9 | C7: 0.71032814
B8: 8187132.3 | C8: 0.69556882

Sheet StrapScenario1
A1: Wash number | B1: ='[1]Final Data (use this)'!C11 | C1: ='[1]Final Data (use this)'!D11 | D1: Total Energy Consumed [MJ/kg resin produced ] | E1: Total Electricity [MJ/kg resin] | F1: Total Direct GHG emissions [Scope 1] [metric tons CO2 equivalent [tCO2e/ton]] | G1: Total Energy indirect GHG emissions (Scope 2) [metric tons CO2 equivalent (t CO2e)] | H1: Water consumed/discarded [m3/yr] | I1: Water Recycled or Reused [m3/yr] | J1: Waste generated - Non Hazardous [kg/yr] | K1: Waste to Disposal[ton/ton] | L1: GWP [tonCO2e/ton resin] | M1: Human toxicity cancer [CTUh/kg resin] | N1: Human toxicity non-cancer [CTUh/kg resin] | O1: Ecotoxicity [CTUe/kg resin] | P1: CAPEX [USD] | Q1: OPEX [USD/yr]
A2: Wash 1 | B2: PE | C2: sec-Butyl Acetate | D2: =[2]Process_results_C1_P1!B2+Shredder!$B$2 | E2: 0 | F2: =L2 | G2: 0 | H2: 1006.01 | I2: 65401.74 | J2: 7403.53 | K2: 0 | L2: =[2]Process_results_C1_P1!C2+Shredder!$K$2 | M2: =[2]Process_results_C1_P1!H2+Shredder!$L$2 | N2: =[2]Process_results_C1_P1!I2+Shredder!$M$2 | O2: =[2]Process_results_C1_P1!J2+Shredder!$N$2 | P2: =[2]Process_results_C1_P1!K2+Shredder!$O$2 | Q2: =[2]Process_results_C1_P1!L2+Shredder!$P$2
A3: Wash 1 | B3: PE | C3: Isobutyl Acetate | D3: =[2]Process_results_C1_P1!B3+Shredder!$B$2 | E3: 0 | F3: =L3 | G3: 0 | H3: 994.95 | I3: 64491.6 | J3: 7463.47 | K3: 0 | L3: =[2]Process_results_C1_P1!C3+Shredder!$K$2 | M3: =[2]Process_results_C1_P1!H3+Shredder!$L$2 | N3: =[2]Process_results_C1_P1!I3+Shredder!$M$2 | O3: =[2]Process_results_C1_P1!J3+Shredder!$N$2 | P3: =[2]Process_results_C1_P1!K3+Shredder!$O$2 | Q3: =[2]Process_results_C1_P1!L3+Shredder!$P$2
A4: Wash 1 | B4: PE | C4: Tetrachloroethylene | D4: =[2]Process_results_C1_P1!B4+Shredder!$B$2 | E4: 0 | F4: =L4 | G4: 0 | H4: 683.96 | I4: 38449.65 | J4: 4419.13 | K4: 0 | L4: =[2]Process_results_C1_P1!C4+Shredder!$K$2 | M4: =[2]Process_results_C1_P1!H4+Shredder!$L$2 | N4: =[2]Process_results_C1_P1!I4+Shredder!$M$2 | O4: =[2]Process_results_C1_P1!J4+Shredder!$N$2 | P4: =[2]Process_results_C1_P1!K4+Shredder!$O$2 | Q4: =[2]Process_results_C1_P1!L4+Shredder!$P$2
A5: Wash 1 | B5: PE | C5: o-Chlorotoluene | D5: =[2]Process_results_C1_P1!B5+Shredder!$B$2 | E5: 0 | F5: =L5 | G5: 0 | H5: 1139.79 | I5: 76633.44 | J5: 6319.81 | K5: 0 | L5: =[2]Process_results_C1_P1!C5+Shredder!$K$2 | M5: =[2]Process_results_C1_P1!H5+Shredder!$L$2 | N5: =[2]Process_results_C1_P1!I5+Shredder!$M$2 | O5: =[2]Process_results_C1_P1!J5+Shredder!$N$2 | P5: =[2]Process_results_C1_P1!K5+Shredder!$O$2 | Q5: =[2]Process_results_C1_P1!L5+Shredder!$P$2
A6: Wash 1 | B6: PE | C6: Methylcyclohexane | D6: =[2]Process_results_C1_P1!B6+Shredder!$B$2 | E6: 0 | F6: =L6 | G6: 0 | H6: 887.08 | I6: 55514.4 | J6: 8129.51 | K6: 0 | L6: =[2]Process_results_C1_P1!C6+Shredder!$K$2 | M6: =[2]Process_results_C1_P1!H6+Shredder!$L$2 | N6: =[2]Process_results_C1_P1!I6+Shredder!$M$2 | O6: =[2]Process_results_C1_P1!J6+Shredder!$N$2 | P6: =[2]Process_results_C1_P1!K6+Shredder!$O$2 | Q6: =[2]Process_results_C1_P1!L6+Shredder!$P$2
A7: Wash 1 | B7: PE | C7: Dodecanol | D7: =[2]Process_results_C1_P1!B7+Shredder!$B$2 | E7: 0 | F7: =L7 | G7: 0 | H7: 2487.39 | I7: 187927.49 | J7: 8514.94 | K7: 0 | L7: =[2]Process_results_C1_P1!C7+Shredder!$K$2 | M7: =[2]Process_results_C1_P1!H7+Shredder!$L$2 | N7: =[2]Process_results_C1_P1!I7+Shredder!$M$2 | O7: =[2]Process_results_C1_P1!J7+Shredder!$N$2 | P7: =[2]Process_results_C1_P1!K7+Shredder!$O$2 | Q7: =[2]Process_results_C1_P1!L7+Shredder!$P$2
A8: Wash 1 | B8: PE | C8: Heptane | D8: =[2]Process_results_C1_P1!B8+Shredder!$B$2 | E8: 0 | F8: =L8 | G8: 0 | H8: 920.27 | I8: 58179.21 | J8: 9006.42 | K8: 0 | L8: =[2]Process_results_C1_P1!C8+Shredder!$K$2 | M8: =[2]Process_results_C1_P1!H8+Shredder!$L$2 | N8: =[2]Process_results_C1_P1!I8+Shredder!$M$2 | O8: =[2]Process_results_C1_P1!J8+Shredder!$N$2 | P8: =[2]Process_results_C1_P1!K8+Shredder!$O$2 | Q8: =[2]Process_results_C1_P1!L8+Shredder!$P$2
A9: Wash 1 | B9: PE | C9: Toluene | D9: =[2]Process_results_C1_P1!B9+Shredder!$B$2 | E9: 0 | F9: =L9 | G9: 0 | H9: 1040.73 | I9: 67836.93 | J9: 11871.24 | K9: 0 | L9: =[2]Process_results_C1_P1!C9+Shredder!$K$2 | M9: =[2]Process_results_C1_P1!H9+Shredder!$L$2 | N9: =[2]Process_results_C1_P1!I9+Shredder!$M$2 | O9: =[2]Process_results_C1_P1!J9+Shredder!$N$2 | P9: =[2]Process_results_C1_P1!K9+Shredder!$O$2 | Q9: =[2]Process_results_C1_P1!L9+Shredder!$P$2
A10: Wash 1 | B10: PE | C10: Xylene | D10: =[2]Process_results_C1_P1!B10+Shredder!$B$2 | E10: 0 | F10: =L10 | G10: 0 | H10: 1159.2 | I10: 78331.71 | J10: 7294.56 | K10: 0 | L10: =[2]Process_results_C1_P1!C10+Shredder!$K$2 | M10: =[2]Process_results_C1_P1!H10+Shredder!$L$2 | N10: =[2]Process_results_C1_P1!I10+Shredder!$M$2 | O10: =[2]Process_results_C1_P1!J10+Shredder!$N$2 | P10: =[2]Process_results_C1_P1!K10+Shredder!$O$2 | Q10: =[2]Process_results_C1_P1!L10+Shredder!$P$2
A11: Wash 1 | B11: EVOH | C11: =[3]Process_results_C1_E1!$A$2 | D11: =[3]Process_results_C1_E1!B2+Shredder!$B$2 | E11: 0 | F11: =L11 | G11: 0 | H11: 1512.92 | I11: 125060.56 | J11: 2426.35 | K11: 0 | L11: =[3]Process_results_C1_E1!C2+Shredder!$K$2 | M11: =[3]Process_results_C1_E1!H2+Shredder!$L$2 | N11: =[3]Process_results_C1_E1!I2+Shredder!$M$2 | O11: =[3]Process_results_C1_E1!J2+Shredder!$N$2 | P11: =[3]Process_results_C1_E1!K2+Shredder!$O$2 | Q11: =[3]Process_results_C1_E1!L2+Shredder!$P$2
A12: Wash 1 | B12: EVOH | C12: =[3]Process_results_C1_E1!$A$3 | D12: =[3]Process_results_C1_E1!B3+Shredder!$B$2 | E12: 0 | F12: =L12 | G12: 0 | H12: 964.84 | I12: 76612.87 | J12: 2837.85 | K12: 0 | L12: =[3]Process_results_C1_E1!C3+Shredder!$K$2 | M12: =[3]Process_results_C1_E1!H3+Shredder!$L$2 | N12: =[3]Process_results_C1_E1!I3+Shredder!$M$2 | O12: =[3]Process_results_C1_E1!J3+Shredder!$N$2 | P12: =[3]Process_results_C1_E1!K3+Shredder!$O$2 | Q12: =[3]Process_results_C1_E1!L3+Shredder!$P$2
A13: Wash 2 | B13: PE | C13: sec-Butyl Acetate | D13: 5.02 | E13: 0 | F13: =L13 | G13: 0 | H13: 966.49 | I13: 62262.96 | J13: 7303.6 | K13: 0 | L13: 1.2005329 | M13: 4.5338019e-08 | N13: 2.5078508e-08 | O13: 1.2777775 | P13: 40931215 | Q13: 1047740.1
A14: Wash 2 | B14: PE | C14: Isobutyl Acetate | D14: 5.02 | E14: 0 | F14: =L14 | G14: 0 | H14: 958.02 | I14: 61569.48 | J14: 7363.19 | K14: 0 | L14: 1.196813 | M14: 4.5246416e-08 | N14: 2.5090223e-08 | O14: 1.2774454 | P14: 41185362 | Q14: 1052268.2
A15: Wash 2 | B15: PE | C15: Tetrachloroethylene | D15: 4.8 | E15: 0 | F15: =L15 | G15: 0 | H15: 656.12 | I15: 36362.45 | J15: 4341.89 | K15: 0 | L15: 1.0965103 | M15: 3.9866638e-08 | N15: 2.1764279e-08 | O15: 1.0740143 | P15: 35754823 | Q15: 938269.24
A16: Wash 2 | B16: PE | C16: o-Chlorotoluene | D16: 5.01 | E16: 0 | F16: =L16 | G16: 0 | H16: 1098.51 | I16: 73352.38 | J16: 6226.9 | K16: 0 | L16: 1.2365479 | M16: 4.6334882e-08 | N16: 2.5177552e-08 | O16: 1.2972699 | P16: 39697204 | Q16: 1028423.1
A17: Wash 2 | B17: PE | C17: Methylcyclohexane | D17: 5.01 | E17: 0 | F17: =L17 | G17: 0 | H17: 846.45 | I17: 52253.34 | J17: 8025.78 | K17: 0 | L17: 1.1562855 | M17: 4.2921731e-08 | N17: 2.2988628e-08 | O17: 1.1816403 | P17: 41755740 | Q17: 1059416.7
A18: Wash 2 | B18: PE | C18: Dodecanol | D18: 5.48 | E18: 0 | F18: =L18 | G18: 0 | H18: 2419.67 | I18: 182520.62 | J18: 8405.55 | K18: 0 | L18: 1.7207436 | M18: 6.5314505e-08 | N18: 3.977586e-08 | O18: 1.9967304 | P18: 45094364 | Q18: 1186252
A19: Wash 2 | B19: PE | C19: Heptane | D19: 5.06 | E19: 0 | F19: =L19 | G19: 0 | H19: 880.03 | I19: 54950.96 | J19: 8897.14 | K19: 0 | L19: 1.1688554 | M19: 4.3001802e-08 | N19: 2.2719875e-08 | O19: 1.1656356 | P19: 43208033 | Q19: 1088889.2
A20: Wash 2 | B20: PE | C20: Toluene | D20: 5.18 | E20: 0 | F20: =L20 | G20: 0 | H20: 993.67 | I20: 64056.57 | J20: 11716.23 | K20: 0 | L20: 1.2141233 | M20: 4.5108743e-08 | N20: 2.3876385e-08 | O20: 1.2302914 | P20: 46986127 | Q20: 1179441.8
A21: Wash 2 | B21: PE | C21: Xylene | D21: 5.06 | E21: 0 | F21: =L21 | G21: 0 | H21: 1117.99 | I21: 75028.67 | J21: 7194.85 | K21: 0 | L21: 1.2384899 | M21: 4.5663809e-08 | N21: 2.4004406e-08 | O21: 1.235194 | P21: 41234664 | Q21: 1058246.1
A22: Wash 2 | B22: EVOH | C22: butane-1,4-diol | D22: =[4]Process_results_C1_E2!B2*Shredder!$B$2 | E22: 0 | F22: =L22 | G22: 0 | H22: =[4]Process_results_C1_E2!F2 | I22: =[4]Process_results_C1_E2!G2 | J22: =[4]Process_results_C1_E2!D2 | K22: 0 | L22: =[4]Process_results_C1_E2!C2+Shredder!$K$2 | M22: =[4]Process_results_C1_E2!H2+Shredder!$L$2 | N22: =[4]Process_results_C1_E2!I2+Shredder!$M$2 | O22: =[4]Process_results_C1_E2!J2+Shredder!$N$2 | P22: =[4]Process_results_C1_E2!K2+Shredder!$O$2 | Q22: =[4]Process_results_C1_E2!L2+Shredder!$P$2
A23: Wash 2 | B23: EVOH | C23: Diethanolamine | D23: =[4]Process_results_C1_E2!B3*Shredder!$B$2 | E23: 0 | F23: =L23 | G23: 0 | H23: =[4]Process_results_C1_E2!F3 | I23: =[4]Process_results_C1_E2!G3 | J23: =[4]Process_results_C1_E2!D3 | K23: 0 | L23: =[4]Process_results_C1_E2!C3+Shredder!$K$2 | M23: =[4]Process_results_C1_E2!H3+Shredder!$L$2 | N23: =[4]Process_results_C1_E2!I3+Shredder!$M$2 | O23: =[4]Process_results_C1_E2!J3+Shredder!$N$2 | P23: =[4]Process_results_C1_E2!K3+Shredder!$O$2 | Q23: =[4]Process_results_C1_E2!L3+Shredder!$P$2
A24: Wash 2 | B24: EVOH | C24: Diethylene glycol | D24: =[4]Process_results_C1_E2!B4*Shredder!$B$2 | E24: 0 | F24: =L24 | G24: 0 | H24: =[4]Process_results_C1_E2!F4 | I24: =[4]Process_results_C1_E2!G4 | J24: =[4]Process_results_C1_E2!D4 | K24: 0 | L24: =[4]Process_results_C1_E2!C4+Shredder!$K$2 | M24: =[4]Process_results_C1_E2!H4+Shredder!$L$2 | N24: =[4]Process_results_C1_E2!I4+Shredder!$M$2 | O24: =[4]Process_results_C1_E2!J4+Shredder!$N$2 | P24: =[4]Process_results_C1_E2!K4+Shredder!$O$2 | Q24: =[4]Process_results_C1_E2!L4+Shredder!$P$2
A25: Wash 2 | B25: EVOH | C25: Ethylene Glycol | D25: =[4]Process_results_C1_E2!B5*Shredder!$B$2 | E25: 0 | F25: =L25 | G25: 0 | H25: =[4]Process_results_C1_E2!F5 | I25: =[4]Process_results_C1_E2!G5 | J25: =[4]Process_results_C1_E2!D5 | K25: 0 | L25: =[4]Process_results_C1_E2!C5+Shredder!$K$2 | M25: =[4]Process_results_C1_E2!H5+Shredder!$L$2 | N25: =[4]Process_results_C1_E2!I5+Shredder!$M$2 | O25: =[4]Process_results_C1_E2!J5+Shredder!$N$2 | P25: =[4]Process_results_C1_E2!K5+Shredder!$O$2 | Q25: =[4]Process_results_C1_E2!L5+Shredder!$P$2
A26: Wash 2 | B26: EVOH | C26: Propylene Glycol | D26: =[4]Process_results_C1_E2!B6*Shredder!$B$2 | E26: 0 | F26: =L26 | G26: 0 | H26: =[4]Process_results_C1_E2!F6 | I26: =[4]Process_results_C1_E2!G6 | J26: =[4]Process_results_C1_E2!D6 | K26: 0 | L26: =[4]Process_results_C1_E2!C6+Shredder!$K$2 | M26: =[4]Process_results_C1_E2!H6+Shredder!$L$2 | N26: =[4]Process_results_C1_E2!I6+Shredder!$M$2 | O26: =[4]Process_results_C1_E2!J6+Shredder!$N$2 | P26: =[4]Process_results_C1_E2!K6+Shredder!$O$2 | Q26: =[4]Process_results_C1_E2!L6+Shredder!$P$2
A27: Wash 2 | B27: EVOH | C27: Pyridazine | D27: =[4]Process_results_C1_E2!B7*Shredder!$B$2 | E27: 0 | F27: =L27 | G27: 0 | H27: =[4]Process_results_C1_E2!F7 | I27: =[4]Process_results_C1_E2!G7 | J27: =[4]Process_results_C1_E2!D7 | K27: 0 | L27: =[4]Process_results_C1_E2!C7+Shredder!$K$2 | M27: =[4]Process_results_C1_E2!H7+Shredder!$L$2 | N27: =[4]Process_results_C1_E2!I7+Shredder!$M$2 | O27: =[4]Process_results_C1_E2!J7+Shredder!$N$2 | P27: =[4]Process_results_C1_E2!K7+Shredder!$O$2 | Q27: =[4]Process_results_C1_E2!L7+Shredder!$P$2
A28: Wash 2 | B28: EVOH | C28: gamma-butyrolactone | D28: =[4]Process_results_C1_E2!B8*Shredder!$B$2 | E28: 0 | F28: =L28 | G28: 0 | H28: =[4]Process_results_C1_E2!F8 | I28: =[4]Process_results_C1_E2!G8 | J28: =[4]Process_results_C1_E2!D8 | K28: 0 | L28: =[4]Process_results_C1_E2!C8+Shredder!$K$2 | M28: =[4]Process_results_C1_E2!H8+Shredder!$L$2 | N28: =[4]Process_results_C1_E2!I8+Shredder!$M$2 | O28: =[4]Process_results_C1_E2!J8+Shredder!$N$2 | P28: =[4]Process_results_C1_E2!K8+Shredder!$O$2 | Q28: =[4]Process_results_C1_E2!L8+Shredder!$P$2

Sheet Shared STRAP Scenario Units
A1: Wash number | B1: Polymer | C1: Solvents | D1: Total Energy Consumed [MJ/yr] | E1: Total Renewable Energy Consumed [MJ/yr] | F1: Total Direct GHG emissions [Scope 1] [metric tons CO2 equivalent [tCO2e/yr]] | G1: Total Energy indirect GHG emissions (Scope 2) [metric tons CO2 equivalent (t CO2e/yr)] | H1: Water consumed/discarded [m3/yr] | I1: Water Recycled or Reused [m3/yr] | J1: Waste generated - Non Hazardous [kg/yr] | K1: Waste to Disposal[ton/yr] | L1: GWP [tonCO2e/yr] | M1: Human toxicity cancer [CTUh/yr] | N1: Human toxicity non-cancer [CTUh/yr] | O1: Ecotoxicity [CTUe/yr] | P1: CAPEX [USD/yr] | Q1: OPEX [USD/yr]
A2: Wash 1 | B2: PE | C2: sec-Butyl Acetate | D2: ='Shared STRAP Scenario'!D2*'[1]New UBs'!$E$57 | E2: ='Shared STRAP Scenario'!E2*'[1]New UBs'!$E$57*0.12 | F2: ='Shared STRAP Scenario'!F2*'[1]New UBs'!$E$57/1000 | G2: ='Shared STRAP Scenario'!G2 | H2: ='Shared STRAP Scenario'!H2 | I2: ='Shared STRAP Scenario'!I2 | J2: ='Shared STRAP Scenario'!J2 | K2: ='Shared STRAP Scenario'!K2 | L2: =F2 | M2: ='Shared STRAP Scenario'!M2*'[1]New UBs'!$E$57 | N2: ='Shared STRAP Scenario'!N2*'[1]New UBs'!$E$57 | O2: ='Shared STRAP Scenario'!O2*'[1]New UBs'!$E$57 | P2: ='Shared STRAP Scenario'!P2/20 | Q2: ='Shared STRAP Scenario'!Q2
A3: Wash 1 | B3: PE | C3: Isobutyl Acetate | D3: ='Shared STRAP Scenario'!D3*'[1]New UBs'!$E$57 | E3: ='Shared STRAP Scenario'!E3*'[1]New UBs'!$E$57*0.12 | F3: ='Shared STRAP Scenario'!F3*'[1]New UBs'!$E$57/1000 | G3: ='Shared STRAP Scenario'!G3 | H3: ='Shared STRAP Scenario'!H3 | I3: ='Shared STRAP Scenario'!I3 | J3: ='Shared STRAP Scenario'!J3 | K3: ='Shared STRAP Scenario'!K3 | L3: =F3 | M3: ='Shared STRAP Scenario'!M3*'[1]New UBs'!$E$57 | N3: ='Shared STRAP Scenario'!N3*'[1]New UBs'!$E$57 | O3: ='Shared STRAP Scenario'!O3*'[1]New UBs'!$E$57 | P3: ='Shared STRAP Scenario'!P3/20 | Q3: ='Shared STRAP Scenario'!Q3
A4: Wash 1 | B4: PE | C4: Tetrachloroethylene | D4: ='Shared STRAP Scenario'!D4*'[1]New UBs'!$E$57 | E4: ='Shared STRAP Scenario'!E4*'[1]New UBs'!$E$57*0.12 | F4: ='Shared STRAP Scenario'!F4*'[1]New UBs'!$E$57/1000 | G4: ='Shared STRAP Scenario'!G4 | H4: ='Shared STRAP Scenario'!H4 | I4: ='Shared STRAP Scenario'!I4 | J4: ='Shared STRAP Scenario'!J4 | K4: ='Shared STRAP Scenario'!K4 | L4: =F4 | M4: ='Shared STRAP Scenario'!M4*'[1]New UBs'!$E$57 | N4: ='Shared STRAP Scenario'!N4*'[1]New UBs'!$E$57 | O4: ='Shared STRAP Scenario'!O4*'[1]New UBs'!$E$57 | P4: ='Shared STRAP Scenario'!P4/20 | Q4: ='Shared STRAP Scenario'!Q4
A5: Wash 1 | B5: PE | C5: o-Chlorotoluene | D5: ='Shared STRAP Scenario'!D5*'[1]New UBs'!$E$57 | E5: ='Shared STRAP Scenario'!E5*'[1]New UBs'!$E$57*0.12 | F5: ='Shared STRAP Scenario'!F5*'[1]New UBs'!$E$57/1000 | G5: ='Shared STRAP Scenario'!G5 | H5: ='Shared STRAP Scenario'!H5 | I5: ='Shared STRAP Scenario'!I5 | J5: ='Shared STRAP Scenario'!J5 | K5: ='Shared STRAP Scenario'!K5 | L5: =F5 | M5: ='Shared STRAP Scenario'!M5*'[1]New UBs'!$E$57 | N5: ='Shared STRAP Scenario'!N5*'[1]New UBs'!$E$57 | O5: ='Shared STRAP Scenario'!O5*'[1]New UBs'!$E$57 | P5: ='Shared STRAP Scenario'!P5/20 | Q5: ='Shared STRAP Scenario'!Q5
A6: Wash 1 | B6: PE | C6: Methylcyclohexane | D6: ='Shared STRAP Scenario'!D6*'[1]New UBs'!$E$57 | E6: ='Shared STRAP Scenario'!E6*'[1]New UBs'!$E$57*0.12 | F6: ='Shared STRAP Scenario'!F6*'[1]New UBs'!$E$57/1000 | G6: ='Shared STRAP Scenario'!G6 | H6: ='Shared STRAP Scenario'!H6 | I6: ='Shared STRAP Scenario'!I6 | J6: ='Shared STRAP Scenario'!J6 | K6: ='Shared STRAP Scenario'!K6 | L6: =F6 | M6: ='Shared STRAP Scenario'!M6*'[1]New UBs'!$E$57 | N6: ='Shared STRAP Scenario'!N6*'[1]New UBs'!$E$57 | O6: ='Shared STRAP Scenario'!O6*'[1]New UBs'!$E$57 | P6: ='Shared STRAP Scenario'!P6/20 | Q6: ='Shared STRAP Scenario'!Q6
A7: Wash 1 | B7: PE | C7: Dodecanol | D7: ='Shared STRAP Scenario'!D7*'[1]New UBs'!$E$57 | E7: ='Shared STRAP Scenario'!E7*'[1]New UBs'!$E$57*0.12 | F7: ='Shared STRAP Scenario'!F7*'[1]New UBs'!$E$57/1000 | G7: ='Shared STRAP Scenario'!G7 | H7: ='Shared STRAP Scenario'!H7 | I7: ='Shared STRAP Scenario'!I7 | J7: ='Shared STRAP Scenario'!J7 | K7: ='Shared STRAP Scenario'!K7 | L7: =F7 | M7: ='Shared STRAP Scenario'!M7*'[1]New UBs'!$E$57 | N7: ='Shared STRAP Scenario'!N7*'[1]New UBs'!$E$57 | O7: ='Shared STRAP Scenario'!O7*'[1]New UBs'!$E$57 | P7: ='Shared STRAP Scenario'!P7/20 | Q7: ='Shared STRAP Scenario'!Q7
A8: Wash 1 | B8: PE | C8: Heptane | D8: ='Shared STRAP Scenario'!D8*'[1]New UBs'!$E$57 | E8: ='Shared STRAP Scenario'!E8*'[1]New UBs'!$E$57*0.12 | F8: ='Shared STRAP Scenario'!F8*'[1]New UBs'!$E$57/1000 | G8: ='Shared STRAP Scenario'!G8 | H8: ='Shared STRAP Scenario'!H8 | I8: ='Shared STRAP Scenario'!I8 | J8: ='Shared STRAP Scenario'!J8 | K8: ='Shared STRAP Scenario'!K8 | L8: =F8 | M8: ='Shared STRAP Scenario'!M8*'[1]New UBs'!$E$57 | N8: ='Shared STRAP Scenario'!N8*'[1]New UBs'!$E$57 | O8: ='Shared STRAP Scenario'!O8*'[1]New UBs'!$E$57 | P8: ='Shared STRAP Scenario'!P8/20 | Q8: ='Shared STRAP Scenario'!Q8
A9: Wash 1 | B9: PE | C9: Toluene | D9: ='Shared STRAP Scenario'!D9*'[1]New UBs'!$E$57 | E9: ='Shared STRAP Scenario'!E9*'[1]New UBs'!$E$57*0.12 | F9: ='Shared STRAP Scenario'!F9*'[1]New UBs'!$E$57/1000 | G9: ='Shared STRAP Scenario'!G9 | H9: ='Shared STRAP Scenario'!H9 | I9: ='Shared STRAP Scenario'!I9 | J9: ='Shared STRAP Scenario'!J9 | K9: ='Shared STRAP Scenario'!K9 | L9: =F9 | M9: ='Shared STRAP Scenario'!M9*'[1]New UBs'!$E$57 | N9: ='Shared STRAP Scenario'!N9*'[1]New UBs'!$E$57 | O9: ='Shared STRAP Scenario'!O9*'[1]New UBs'!$E$57 | P9: ='Shared STRAP Scenario'!P9/20 | Q9: ='Shared STRAP Scenario'!Q9
A10: Wash 1 | B10: PE | C10: Xylene | D10: ='Shared STRAP Scenario'!D10*'[1]New UBs'!$E$57 | E10: ='Shared STRAP Scenario'!E10*'[1]New UBs'!$E$57*0.12 | F10: ='Shared STRAP Scenario'!F10*'[1]New UBs'!$E$57/1000 | G10: ='Shared STRAP Scenario'!G10 | H10: ='Shared STRAP Scenario'!H10 | I10: ='Shared STRAP Scenario'!I10 | J10: ='Shared STRAP Scenario'!J10 | K10: ='Shared STRAP Scenario'!K10 | L10: =F10 | M10: ='Shared STRAP Scenario'!M10*'[1]New UBs'!$E$57 | N10: ='Shared STRAP Scenario'!N10*'[1]New UBs'!$E$57 | O10: ='Shared STRAP Scenario'!O10*'[1]New UBs'!$E$57 | P10: ='Shared STRAP Scenario'!P10/20 | Q10: ='Shared STRAP Scenario'!Q10
A11: Wash 1 | B11: EVOH | C11: =[5]Process_results_C2_E1!$A$2 | D11: ='Shared STRAP Scenario'!D11*'[1]New UBs'!$E$58 | E11: ='Shared STRAP Scenario'!E11*'[1]New UBs'!$E$58*0.12 | F11: ='Shared STRAP Scenario'!F11*'[1]New UBs'!$E$58/1000 | G11: ='Shared STRAP Scenario'!G11 | H11: ='Shared STRAP Scenario'!H11 | I11: ='Shared STRAP Scenario'!I11 | J11: ='Shared STRAP Scenario'!J11 | K11: ='Shared STRAP Scenario'!K11 | L11: =F11 | M11: ='Shared STRAP Scenario'!M11*'[1]New UBs'!$E$58 | N11: ='Shared STRAP Scenario'!N11*'[1]New UBs'!$E$58 | O11: ='Shared STRAP Scenario'!O11*'[1]New UBs'!$E$58 | P11: ='Shared STRAP Scenario'!P11/20 | Q11: ='Shared STRAP Scenario'!Q11
A12: Wash 1 | B12: EVOH | C12: Pyridazine | D12: ='Shared STRAP Scenario'!D12*'[1]New UBs'!$E$58 | E12: ='Shared STRAP Scenario'!E12*'[1]New UBs'!$E$58*0.12 | F12: ='Shared STRAP Scenario'!F12*'[1]New UBs'!$E$58/1000 | G12: ='Shared STRAP Scenario'!G12 | H12: ='Shared STRAP Scenario'!H12 | I12: ='Shared STRAP Scenario'!I12 | J12: ='Shared STRAP Scenario'!J12 | K12: ='Shared STRAP Scenario'!K12 | L12: =F12 | M12: ='Shared STRAP Scenario'!M12*'[1]New UBs'!$E$58 | N12: ='Shared STRAP Scenario'!N12*'[1]New UBs'!$E$58 | O12: ='Shared STRAP Scenario'!O12*'[1]New UBs'!$E$58 | P12: ='Shared STRAP Scenario'!P12/20 | Q12: ='Shared STRAP Scenario'!Q12
A13: Wash 2 | B13: PE | C13: sec-Butyl Acetate | D13: ='Shared STRAP Scenario'!D13*'[1]New UBs'!$J$58 | E13: ='Shared STRAP Scenario'!E13*'[1]New UBs'!$J$58*0.12 | F13: ='Shared STRAP Scenario'!F13*'[1]New UBs'!$J$58/1000 | G13: ='Shared STRAP Scenario'!G13 | H13: ='Shared STRAP Scenario'!H13 | I13: ='Shared STRAP Scenario'!I13 | J13: ='Shared STRAP Scenario'!J13 | K13: ='Shared STRAP Scenario'!K13 | L13: =F13 | M13: ='Shared STRAP Scenario'!M13*'[1]New UBs'!$J$58 | N13: ='Shared STRAP Scenario'!N13*'[1]New UBs'!$J$58 | O13: ='Shared STRAP Scenario'!O13*'[1]New UBs'!$J$58 | P13: ='Shared STRAP Scenario'!P13/20 | Q13: ='Shared STRAP Scenario'!Q13
A14: Wash 2 | B14: PE | C14: Isobutyl Acetate | D14: ='Shared STRAP Scenario'!D14*'[1]New UBs'!$J$58 | E14: ='Shared STRAP Scenario'!E14*'[1]New UBs'!$J$58*0.12 | F14: ='Shared STRAP Scenario'!F14*'[1]New UBs'!$J$58/1000 | G14: ='Shared STRAP Scenario'!G14 | H14: ='Shared STRAP Scenario'!H14 | I14: ='Shared STRAP Scenario'!I14 | J14: ='Shared STRAP Scenario'!J14 | K14: ='Shared STRAP Scenario'!K14 | L14: =F14 | M14: ='Shared STRAP Scenario'!M14*'[1]New UBs'!$J$58 | N14: ='Shared STRAP Scenario'!N14*'[1]New UBs'!$J$58 | O14: ='Shared STRAP Scenario'!O14*'[1]New UBs'!$J$58 | P14: ='Shared STRAP Scenario'!P14/20 | Q14: ='Shared STRAP Scenario'!Q14
A15: Wash 2 | B15: PE | C15: Tetrachloroethylene | D15: ='Shared STRAP Scenario'!D15*'[1]New UBs'!$J$58 | E15: ='Shared STRAP Scenario'!E15*'[1]New UBs'!$J$58*0.12 | F15: ='Shared STRAP Scenario'!F15*'[1]New UBs'!$J$58/1000 | G15: ='Shared STRAP Scenario'!G15 | H15: ='Shared STRAP Scenario'!H15 | I15: ='Shared STRAP Scenario'!I15 | J15: ='Shared STRAP Scenario'!J15 | K15: ='Shared STRAP Scenario'!K15 | L15: =F15 | M15: ='Shared STRAP Scenario'!M15*'[1]New UBs'!$J$58 | N15: ='Shared STRAP Scenario'!N15*'[1]New UBs'!$J$58 | O15: ='Shared STRAP Scenario'!O15*'[1]New UBs'!$J$58 | P15: ='Shared STRAP Scenario'!P15/20 | Q15: ='Shared STRAP Scenario'!Q15
A16: Wash 2 | B16: PE | C16: o-Chlorotoluene | D16: ='Shared STRAP Scenario'!D16*'[1]New UBs'!$J$58 | E16: ='Shared STRAP Scenario'!E16*'[1]New UBs'!$J$58*0.12 | F16: ='Shared STRAP Scenario'!F16*'[1]New UBs'!$J$58/1000 | G16: ='Shared STRAP Scenario'!G16 | H16: ='Shared STRAP Scenario'!H16 | I16: ='Shared STRAP Scenario'!I16 | J16: ='Shared STRAP Scenario'!J16 | K16: ='Shared STRAP Scenario'!K16 | L16: =F16 | M16: ='Shared STRAP Scenario'!M16*'[1]New UBs'!$J$58 | N16: ='Shared STRAP Scenario'!N16*'[1]New UBs'!$J$58 | O16: ='Shared STRAP Scenario'!O16*'[1]New UBs'!$J$58 | P16: ='Shared STRAP Scenario'!P16/20 | Q16: ='Shared STRAP Scenario'!Q16
A17: Wash 2 | B17: PE | C17: Methylcyclohexane | D17: ='Shared STRAP Scenario'!D17*'[1]New UBs'!$J$58 | E17: ='Shared STRAP Scenario'!E17*'[1]New UBs'!$J$58*0.12 | F17: ='Shared STRAP Scenario'!F17*'[1]New UBs'!$J$58/1000 | G17: ='Shared STRAP Scenario'!G17 | H17: ='Shared STRAP Scenario'!H17 | I17: ='Shared STRAP Scenario'!I17 | J17: ='Shared STRAP Scenario'!J17 | K17: ='Shared STRAP Scenario'!K17 | L17: =F17 | M17: ='Shared STRAP Scenario'!M17*'[1]New UBs'!$J$58 | N17: ='Shared STRAP Scenario'!N17*'[1]New UBs'!$J$58 | O17: ='Shared STRAP Scenario'!O17*'[1]New UBs'!$J$58 | P17: ='Shared STRAP Scenario'!P17/20 | Q17: ='Shared STRAP Scenario'!Q17
A18: Wash 2 | B18: PE | C18: Dodecanol | D18: ='Shared STRAP Scenario'!D18*'[1]New UBs'!$J$58 | E18: ='Shared STRAP Scenario'!E18*'[1]New UBs'!$J$58*0.12 | F18: ='Shared STRAP Scenario'!F18*'[1]New UBs'!$J$58/1000 | G18: ='Shared STRAP Scenario'!G18 | H18: ='Shared STRAP Scenario'!H18 | I18: ='Shared STRAP Scenario'!I18 | J18: ='Shared STRAP Scenario'!J18 | K18: ='Shared STRAP Scenario'!K18 | L18: =F18 | M18: ='Shared STRAP Scenario'!M18*'[1]New UBs'!$J$58 | N18: ='Shared STRAP Scenario'!N18*'[1]New UBs'!$J$58 | O18: ='Shared STRAP Scenario'!O18*'[1]New UBs'!$J$58 | P18: ='Shared STRAP Scenario'!P18/20 | Q18: ='Shared STRAP Scenario'!Q18
A19: Wash 2 | B19: PE | C19: Heptane | D19: ='Shared STRAP Scenario'!D19*'[1]New UBs'!$J$58 | E19: ='Shared STRAP Scenario'!E19*'[1]New UBs'!$J$58*0.12 | F19: ='Shared STRAP Scenario'!F19*'[1]New UBs'!$J$58/1000 | G19: ='Shared STRAP Scenario'!G19 | H19: ='Shared STRAP Scenario'!H19 | I19: ='Shared STRAP Scenario'!I19 | J19: ='Shared STRAP Scenario'!J19 | K19: ='Shared STRAP Scenario'!K19 | L19: =F19 | M19: ='Shared STRAP Scenario'!M19*'[1]New UBs'!$J$58 | N19: ='Shared STRAP Scenario'!N19*'[1]New UBs'!$J$58 | O19: ='Shared STRAP Scenario'!O19*'[1]New UBs'!$J$58 | P19: ='Shared STRAP Scenario'!P19/20 | Q19: ='Shared STRAP Scenario'!Q19
A20: Wash 2 | B20: PE | C20: Toluene | D20: ='Shared STRAP Scenario'!D20*'[1]New UBs'!$J$58 | E20: ='Shared STRAP Scenario'!E20*'[1]New UBs'!$J$58*0.12 | F20: ='Shared STRAP Scenario'!F20*'[1]New UBs'!$J$58/1000 | G20: ='Shared STRAP Scenario'!G20 | H20: ='Shared STRAP Scenario'!H20 | I20: ='Shared STRAP Scenario'!I20 | J20: ='Shared STRAP Scenario'!J20 | K20: ='Shared STRAP Scenario'!K20 | L20: =F20 | M20: ='Shared STRAP Scenario'!M20*'[1]New UBs'!$J$58 | N20: ='Shared STRAP Scenario'!N20*'[1]New UBs'!$J$58 | O20: ='Shared STRAP Scenario'!O20*'[1]New UBs'!$J$58 | P20: ='Shared STRAP Scenario'!P20/20 | Q20: ='Shared STRAP Scenario'!Q20
A21: Wash 2 | B21: PE | C21: Xylene | D21: ='Shared STRAP Scenario'!D21*'[1]New UBs'!$J$58 | E21: ='Shared STRAP Scenario'!E21*'[1]New UBs'!$J$58*0.12 | F21: ='Shared STRAP Scenario'!F21*'[1]New UBs'!$J$58/1000 | G21: ='Shared STRAP Scenario'!G21 | H21: ='Shared STRAP Scenario'!H21 | I21: ='Shared STRAP Scenario'!I21 | J21: ='Shared STRAP Scenario'!J21 | K21: ='Shared STRAP Scenario'!K21 | L21: =F21 | M21: ='Shared STRAP Scenario'!M21*'[1]New UBs'!$J$58 | N21: ='Shared STRAP Scenario'!N21*'[1]New UBs'!$J$58 | O21: ='Shared STRAP Scenario'!O21*'[1]New UBs'!$J$58 | P21: ='Shared STRAP Scenario'!P21/20 | Q21: ='Shared STRAP Scenario'!Q21
A22: Wash 2 | B22: EVOH | C22: butane-1,4-diol | D22: ='Shared STRAP Scenario'!D22*'[1]New UBs'!$J$57 | E22: ='Shared STRAP Scenario'!E22*'[1]New UBs'!$J$57*0.12 | F22: ='Shared STRAP Scenario'!F22*'[1]New UBs'!$J$57/1000 | G22: ='Shared STRAP Scenario'!G22 | H22: ='Shared STRAP Scenario'!H22 | I22: ='Shared STRAP Scenario'!I22 | J22: ='Shared STRAP Scenario'!J22 | K22: ='Shared STRAP Scenario'!K22 | L22: =F22 | M22: ='Shared STRAP Scenario'!M22*'[1]New UBs'!$J$57 | N22: ='Shared STRAP Scenario'!N22*'[1]New UBs'!$J$57 | O22: ='Shared STRAP Scenario'!O22*'[1]New UBs'!$J$57 | P22: ='Shared STRAP Scenario'!P22/20 | Q22: ='Shared STRAP Scenario'!Q22
A23: Wash 2 | B23: EVOH | C23: Diethanolamine | D23: ='Shared STRAP Scenario'!D23*'[1]New UBs'!$J$57 | E23: ='Shared STRAP Scenario'!E23*'[1]New UBs'!$J$57*0.12 | F23: ='Shared STRAP Scenario'!F23*'[1]New UBs'!$J$57/1000 | G23: ='Shared STRAP Scenario'!G23 | H23: ='Shared STRAP Scenario'!H23 | I23: ='Shared STRAP Scenario'!I23 | J23: ='Shared STRAP Scenario'!J23 | K23: ='Shared STRAP Scenario'!K23 | L23: =F23 | M23: ='Shared STRAP Scenario'!M23*'[1]New UBs'!$J$57 | N23: ='Shared STRAP Scenario'!N23*'[1]New UBs'!$J$57 | O23: ='Shared STRAP Scenario'!O23*'[1]New UBs'!$J$57 | P23: ='Shared STRAP Scenario'!P23/20 | Q23: ='Shared STRAP Scenario'!Q23
A24: Wash 2 | B24: EVOH | C24: Diethylene glycol | D24: ='Shared STRAP Scenario'!D24*'[1]New UBs'!$J$57 | E24: ='Shared STRAP Scenario'!E24*'[1]New UBs'!$J$57*0.12 | F24: ='Shared STRAP Scenario'!F24*'[1]New UBs'!$J$57/1000 | G24: ='Shared STRAP Scenario'!G24 | H24: ='Shared STRAP Scenario'!H24 | I24: ='Shared STRAP Scenario'!I24 | J24: ='Shared STRAP Scenario'!J24 | K24: ='Shared STRAP Scenario'!K24 | L24: =F24 | M24: ='Shared STRAP Scenario'!M24*'[1]New UBs'!$J$57 | N24: ='Shared STRAP Scenario'!N24*'[1]New UBs'!$J$57 | O24: ='Shared STRAP Scenario'!O24*'[1]New UBs'!$J$57 | P24: ='Shared STRAP Scenario'!P24/20 | Q24: ='Shared STRAP Scenario'!Q24
A25: Wash 2 | B25: EVOH | C25: Ethylene Glycol | D25: ='Shared STRAP Scenario'!D25*'[1]New UBs'!$J$57 | E25: ='Shared STRAP Scenario'!E25*'[1]New UBs'!$J$57*0.12 | F25: ='Shared STRAP Scenario'!F25*'[1]New UBs'!$J$57/1000 | G25: ='Shared STRAP Scenario'!G25 | H25: ='Shared STRAP Scenario'!H25 | I25: ='Shared STRAP Scenario'!I25 | J25: ='Shared STRAP Scenario'!J25 | K25: ='Shared STRAP Scenario'!K25 | L25: =F25 | M25: ='Shared STRAP Scenario'!M25*'[1]New UBs'!$J$57 | N25: ='Shared STRAP Scenario'!N25*'[1]New UBs'!$J$57 | O25: ='Shared STRAP Scenario'!O25*'[1]New UBs'!$J$57 | P25: ='Shared STRAP Scenario'!P25/20 | Q25: ='Shared STRAP Scenario'!Q25
A26: Wash 2 | B26: EVOH | C26: Propylene Glycol | D26: ='Shared STRAP Scenario'!D26*'[1]New UBs'!$J$57 | E26: ='Shared STRAP Scenario'!E26*'[1]New UBs'!$J$57*0.12 | F26: ='Shared STRAP Scenario'!F26*'[1]New UBs'!$J$57/1000 | G26: ='Shared STRAP Scenario'!G26 | H26: ='Shared STRAP Scenario'!H26 | I26: ='Shared STRAP Scenario'!I26 | J26: ='Shared STRAP Scenario'!J26 | K26: ='Shared STRAP Scenario'!K26 | L26: =F26 | M26: ='Shared STRAP Scenario'!M26*'[1]New UBs'!$J$57 | N26: ='Shared STRAP Scenario'!N26*'[1]New UBs'!$J$57 | O26: ='Shared STRAP Scenario'!O26*'[1]New UBs'!$J$57 | P26: ='Shared STRAP Scenario'!P26/20 | Q26: ='Shared STRAP Scenario'!Q26
A27: Wash 2 | B27: EVOH | C27: Pyridazine | D27: ='Shared STRAP Scenario'!D27*'[1]New UBs'!$J$57 | E27: ='Shared STRAP Scenario'!E27*'[1]New UBs'!$J$57*0.12 | F27: ='Shared STRAP Scenario'!F27*'[1]New UBs'!$J$57/1000 | G27: ='Shared STRAP Scenario'!G27 | H27: ='Shared STRAP Scenario'!H27 | I27: ='Shared STRAP Scenario'!I27 | J27: ='Shared STRAP Scenario'!J27 | K27: ='Shared STRAP Scenario'!K27 | L27: =F27 | M27: ='Shared STRAP Scenario'!M27*'[1]New UBs'!$J$57 | N27: ='Shared STRAP Scenario'!N27*'[1]New UBs'!$J$57 | O27: ='Shared STRAP Scenario'!O27*'[1]New UBs'!$J$57 | P27: ='Shared STRAP Scenario'!P27/20 | Q27: ='Shared STRAP Scenario'!Q27
A28: Wash 2 | B28: EVOH | C28: gamma-butyrolactone | D28: ='Shared STRAP Scenario'!D28*'[1]New UBs'!$J$57 | E28: ='Shared STRAP Scenario'!E28*'[1]New UBs'!$J$57*0.12 | F28: ='Shared STRAP Scenario'!F28*'[1]New UBs'!$J$57/1000 | G28: ='Shared STRAP Scenario'!G28 | H28: ='Shared STRAP Scenario'!H28 | I28: ='Shared STRAP Scenario'!I28 | J28: ='Shared STRAP Scenario'!J28 | K28: ='Shared STRAP Scenario'!K28 | L28: =F28 | M28: ='Shared STRAP Scenario'!M28*'[1]New UBs'!$J$57 | N28: ='Shared STRAP Scenario'!N28*'[1]New UBs'!$J$57 | O28: ='Shared STRAP Scenario'!O28*'[1]New UBs'!$J$57 | P28: ='Shared STRAP Scenario'!P28/20 | Q28: ='Shared STRAP Scenario'!Q28

Sheet Shared STRAP Scenario
A1: Wash number | B1: ='[1]Final Data (use this)'!C11 | C1: ='[1]Final Data (use this)'!D11 | D1: Total Energy Consumed [MJ/kg resin produced ] | E1: Total Electricity [MJ/kg resin] | F1: Total Direct GHG emissions [Scope 1] [metric tons CO2 equivalent [tCO2e/ton]] | G1: Total Energy indirect GHG emissions (Scope 2) [metric tons CO2 equivalent (t CO2e)] | H1: Water consumed/discarded [m3/yr] | I1: Water Recycled or Reused [m3/yr] | J1: Waste generated - Non Hazardous [kg/yr] | K1: Waste to Disposal[ton/ton] | L1: GWP [tonCO2e/ton resin] | M1: Human toxicity cancer [CTUh/kg resin] | N1: Human toxicity non-cancer [CTUh/kg resin] | O1: Ecotoxicity [CTUe/kg resin] | P1: CAPEX [USD] | Q1: OPEX [USD/yr]
A2: Wash 1 | B2: PE | C2: sec-Butyl Acetate | D2: =[6]Process_results20_C2_P1!B2+[7]Process_results_shredderC2!$B$2 | E2: =[6]Process_results20_C2_P1!C2+[7]Process_results_shredderC2!$C$2 | F2: =[6]Process_results20_C2_P1!D2+[7]Process_results_shredderC2!$D$2 | G2: 0 | H2: 1383.74 | I2: 125794.99 | J2: 18508.81 | K2: 0 | L2: =F2 | M2: =[6]Process_results20_C2_P1!$I$2+[7]Process_results_shredderC2!$E$2 | N2: =[6]Process_results20_C2_P1!$J$2+[7]Process_results_shredderC2!$F$2 | O2: =[6]Process_results20_C2_P1!$K$2+[7]Process_results_shredderC2!$G$2 | P2: =[6]Process_results20_C2_P1!$L$2+[7]Process_results_shredderC2!$H$2 | Q2: =[6]Process_results20_C2_P1!$M$2+[7]Process_results_shredderC2!$I$2
A3: Wash 1 | B3: PE | C3: Isobutyl Acetate | D3: =[6]Process_results20_C2_P1!B3+[7]Process_results_shredderC2!$B$2 | E3: =[6]Process_results20_C2_P1!C3+[7]Process_results_shredderC2!$C$2 | F3: =[6]Process_results20_C2_P1!D3+[7]Process_results_shredderC2!$D$2 | G3: 0 | H3: 1360.23 | I3: 123657.44 | J3: 18658.68 | K3: 0 | L3: =F3 | M3: =[6]Process_results20_C2_P1!$I$2+[7]Process_results_shredderC2!$E$2 | N3: =[6]Process_results20_C2_P1!$J$2+[7]Process_results_shredderC2!$F$2 | O3: =[6]Process_results20_C2_P1!$K$2+[7]Process_results_shredderC2!$G$2 | P3: =[6]Process_results20_C2_P1!$L$2+[7]Process_results_shredderC2!$H$2 | Q3: =[6]Process_results20_C2_P1!$M$2+[7]Process_results_shredderC2!$I$2
A4: Wash 1 | B4: PE | C4: Tetrachloroethylene | D4: =[6]Process_results20_C2_P1!B4+[7]Process_results_shredderC2!$B$2 | E4: =[6]Process_results20_C2_P1!C4+[7]Process_results_shredderC2!$C$2 | F4: =[6]Process_results20_C2_P1!D4+[7]Process_results_shredderC2!$D$2 | G4: 0 | H4: 679.58 | I4: 61779.89 | J4: 11047.83 | K4: 0 | L4: =F4 | M4: =[6]Process_results20_C2_P1!$I$2+[7]Process_results_shredderC2!$E$2 | N4: =[6]Process_results20_C2_P1!$J$2+[7]Process_results_shredderC2!$F$2 | O4: =[6]Process_results20_C2_P1!$K$2+[7]Process_results_shredderC2!$G$2 | P4: =[6]Process_results20_C2_P1!$L$2+[7]Process_results_shredderC2!$H$2 | Q4: =[6]Process_results20_C2_P1!$M$2+[7]Process_results_shredderC2!$I$2
A5: Wash 1 | B5: PE | C5: o-Chlorotoluene | D5: =[6]Process_results20_C2_P1!B5+[7]Process_results_shredderC2!$B$2 | E5: =[6]Process_results20_C2_P1!C5+[7]Process_results_shredderC2!$C$2 | F5: =[6]Process_results20_C2_P1!D5+[7]Process_results_shredderC2!$D$2 | G5: 0 | H5: 1677.81 | I5: 152528.39 | J5: 15799.53 | K5: 0 | L5: =F5 | M5: =[6]Process_results20_C2_P1!$I$2+[7]Process_results_shredderC2!$E$2 | N5: =[6]Process_results20_C2_P1!$J$2+[7]Process_results_shredderC2!$F$2 | O5: =[6]Process_results20_C2_P1!$K$2+[7]Process_results_shredderC2!$G$2 | P5: =[6]Process_results20_C2_P1!$L$2+[7]Process_results_shredderC2!$H$2 | Q5: =[6]Process_results20_C2_P1!$M$2+[7]Process_results_shredderC2!$I$2
